Traceback (most recent call last):
  File "/Users/crovella/miniconda3/lib/python3.9/site-packages/jupyter_cache/executors/utils.py", line 58, in single_nb_execution
    executenb(
  File "/Users/crovella/miniconda3/lib/python3.9/site-packages/nbclient/client.py", line 1204, in execute
    return NotebookClient(nb=nb, resources=resources, km=km, **kwargs).execute()
  File "/Users/crovella/miniconda3/lib/python3.9/site-packages/nbclient/util.py", line 84, in wrapped
    return just_run(coro(*args, **kwargs))
  File "/Users/crovella/miniconda3/lib/python3.9/site-packages/nbclient/util.py", line 62, in just_run
    return loop.run_until_complete(coro)
  File "/Users/crovella/miniconda3/lib/python3.9/asyncio/base_events.py", line 647, in run_until_complete
    return future.result()
  File "/Users/crovella/miniconda3/lib/python3.9/site-packages/nbclient/client.py", line 663, in async_execute
    await self.async_execute_cell(
  File "/Users/crovella/miniconda3/lib/python3.9/site-packages/nbclient/client.py", line 965, in async_execute_cell
    await self._check_raise_for_error(cell, cell_index, exec_reply)
  File "/Users/crovella/miniconda3/lib/python3.9/site-packages/nbclient/client.py", line 862, in _check_raise_for_error
    raise CellExecutionError.from_cell_and_msg(cell, exec_reply_content)
nbclient.exceptions.CellExecutionError: An error occurred while executing the following cell:
------------------
dot_data = tree.export_graphviz(dtc, out_file=None,
                         feature_names=['X','Y'],
                         class_names=['Red','Green'],
                         filled=True, rounded=True,  
                         special_characters=True) 
import pydotplus
graph = pydotplus.graph_from_dot_data(dot_data) 
# graph.write_pdf("dt.pdf") 
Image(graph.create_png())
------------------

[0;31m---------------------------------------------------------------------------[0m
[0;31mModuleNotFoundError[0m                       Traceback (most recent call last)
Cell [0;32mIn[36], line 6[0m
[1;32m      1[0m dot_data [38;5;241m=[39m tree[38;5;241m.[39mexport_graphviz(dtc, out_file[38;5;241m=[39m[38;5;28;01mNone[39;00m,
[1;32m      2[0m                          feature_names[38;5;241m=[39m[[38;5;124m'[39m[38;5;124mX[39m[38;5;124m'[39m,[38;5;124m'[39m[38;5;124mY[39m[38;5;124m'[39m],
[1;32m      3[0m                          class_names[38;5;241m=[39m[[38;5;124m'[39m[38;5;124mRed[39m[38;5;124m'[39m,[38;5;124m'[39m[38;5;124mGreen[39m[38;5;124m'[39m],
[1;32m      4[0m                          filled[38;5;241m=[39m[38;5;28;01mTrue[39;00m, rounded[38;5;241m=[39m[38;5;28;01mTrue[39;00m,  
[1;32m      5[0m                          special_characters[38;5;241m=[39m[38;5;28;01mTrue[39;00m) 
[0;32m----> 6[0m [38;5;28;01mimport[39;00m [38;5;21;01mpydotplus[39;00m
[1;32m      7[0m graph [38;5;241m=[39m pydotplus[38;5;241m.[39mgraph_from_dot_data(dot_data) 
[1;32m      8[0m [38;5;66;03m# graph.write_pdf("dt.pdf") [39;00m

[0;31mModuleNotFoundError[0m: No module named 'pydotplus'
ModuleNotFoundError: No module named 'pydotplus'

